Workbook
Name Slicer_exporter_country: #N/A
Name Slicer_geopolitical_sensitivity: #N/A
Name Slicer_hardware_type: #N/A
Name Slicer_year: #N/A

Sheet Trade_Flows
A1: trade_id | B1: year | C1: quarter | D1: year_quarter | E1: exporter_country_code | F1: exporter_country | G1: exporter_region | H1: importer_country_code | I1: importer_country | J1: importer_region | K1: hardware_type | L1: Hardware_Segment | M1: hardware_category | N1: volume_units | O1: trade_value_usd_millions | P1: primary_supplier | Q1: trade_route | R1: export_control_applied | S1: restriction_factor | T1: geopolitical_sensitivity | U1: geo_risk_score_exporter | V1: geo_risk_score_importer | W1: data_source | X1: is_synthetic
A2: Tf000001 | B2: 2015 | C2: 1 | D2: 2015-Q1 | E2: Tw | F2: Taiwan | G2: Asia-Pacific | H2: Us | I2: United States | J2: North America | K2: Advanced_Logic_Chip | L2: =_xlfn.XLOOKUP(Trade_Flows[[#This Row],[hardware_type]],Helper_sheet!$D$2:$D$15,Helper_sheet!$E$2:$E$15,0,0) -> Chip | M2: Advanced | N2: 10591 | O2: 617.82 | P2: Intel Foundry Services | Q2: Trans-Pacific / Suez | R2: 0 | S2: 1 | T2: Low | U2: 8.34 | V2: 3.27 | W2: Un Comtrade/Wits/Sia Reports | X2: 0
A3: Tf000002 | B3: 2015 | C3: 2 | D3: 2015-Q2 | E3: Tw | F3: Taiwan | G3: Asia-Pacific | H3: Us | I3: United States | J3: North America | K3: Advanced_Logic_Chip | L3: =_xlfn.XLOOKUP(Trade_Flows[[#This Row],[hardware_type]],Helper_sheet!$D$2:$D$15,Helper_sheet!$E$2:$E$15,0,0) -> Chip | M3: Advanced | N3: 12775 | O3: 745.24 | P3: Tsmc | Q3: Trans-Pacific / Suez | R3: 0 | S3: 1 | T3: Low | U3: 8.1 | V3: 3.1 | W3: Un Comtrade/Wits/Sia Reports | X3: 0
A4: Tf000003 | B4: 2015 | C4: 3 | D4: 2015-Q3 | E4: Tw | F4: Taiwan | G4: Asia-Pacific | H4: Us | I4: United States | J4: North America | K4: Advanced_Logic_Chip | L4: =_xlfn.XLOOKUP(Trade_Flows[[#This Row],[hardware_type]],Helper_sheet!$D$2:$D$15,Helper_sheet!$E$2:$E$15,0,0) -> Chip | M4: Advanced | N4: 11692 | O4: 682.08 | P4: Tsmc | Q4: Trans-Pacific / Suez | R4: 0 | S4: 1 | T4: Low | U4: 8.31 | V4: 3.23 | W4: Un Comtrade/Wits/Sia Reports | X4: 0
A5: Tf000004 | B5: 2015 | C5: 4 | D5: 2015-Q4 | E5: Tw | F5: Taiwan | G5: Asia-Pacific | H5: Us | I5: United States | J5: North America | K5: Advanced_Logic_Chip | L5: =_xlfn.XLOOKUP(Trade_Flows[[#This Row],[hardware_type]],Helper_sheet!$D$2:$D$15,Helper_sheet!$E$2:$E$15,0,0) -> Chip | M5: Advanced | N5: 12095 | O5: 705.56 | P5: Intel Foundry Services | Q5: Trans-Pacific / Suez | R5: 0 | S5: 1 | T5: Low | U5: 8.06 | V5: 3.34 | W5: Un Comtrade/Wits/Sia Reports | X5: 0
A6: Tf000005 | B6: 2016 | C6: 1 | D6: 2016-Q1 | E6: Tw | F6: Taiwan | G6: Asia-Pacific | H6: Us | I6: United States | J6: North America | K6: Advanced_Logic_Chip | L6: =_xlfn.XLOOKUP(Trade_Flows[[#This Row],[hardware_type]],Helper_sheet!$D$2:$D$15,Helper_sheet!$E$2:$E$15,0,0) -> Chip | M6: Advanced | N6: 13363 | O6: 779.53 | P6: Samsung Foundry | Q6: Trans-Pacific / Suez | R6: 0 | S6: 1 | T6: Low | U6: 8.11 | V6: 3.1 | W6: Un Comtrade/Wits/Sia Reports | X6: 0
A7: Tf000006 | B7: 2016 | C7: 2 | D7: 2016-Q2 | E7: Tw | F7: Taiwan | G7: Asia-Pacific | H7: Us | I7: United States | J7: North America | K7: Advanced_Logic_Chip | L7: =_xlfn.XLOOKUP(Trade_Flows[[#This Row],[hardware_type]],Helper_sheet!$D$2:$D$15,Helper_sheet!$E$2:$E$15,0,0) -> Chip | M7: Advanced | N7: 13069 | O7: 762.38 | P7: Tsmc | Q7: Trans-Pacific / Suez | R7: 0 | S7: 1 | T7: Low | U7: 8.14 | V7: 3.21 | W7: Un Comtrade/Wits/Sia Reports | X7: 0
A8: Tf000007 | B8: 2016 | C8: 3 | D8: 2016-Q3 | E8: Tw | F8: Taiwan | G8: Asia-Pacific | H8: Us | I8: United States | J8: North America | K8: Advanced_Logic_Chip | L8: =_xlfn.XLOOKUP(Trade_Flows[[#This Row],[hardware_type]],Helper_sheet!$D$2:$D$15,Helper_sheet!$E$2:$E$15,0,0) -> Chip | M8: Advanced | N8: 14581 | O8: 850.61 | P8: Tsmc | Q8: Trans-Pacific / Suez | R8: 0 | S8: 1 | T8: Low | U8: 8.14 | V8: 3.23 | W8: Un Comtrade/Wits/Sia Reports | X8: 0
A9: Tf000008 | B9: 2016 | C9: 4 | D9: 2016-Q4 | E9: Tw | F9: Taiwan | G9: Asia-Pacific | H9: Us | I9: United States | J9: North America | K9: Advanced_Logic_Chip | L9: =_xlfn.XLOOKUP(Trade_Flows[[#This Row],[hardware_type]],Helper_sheet!$D$2:$D$15,Helper_sheet!$E$2:$E$15,0,0) -> Chip | M9: Advanced | N9: 11926 | O9: 695.71 | P9: Tsmc | Q9: Trans-Pacific / Suez | R9: 0 | S9: 1 | T9: Low | U9: 8.14 | V9: 3.16 | W9: Un Comtrade/Wits/Sia Reports | X9: 0
A10: Tf000009 | B10: 2017 | C10: 1 | D10: 2017-Q1 | E10: Tw | F10: Taiwan | G10: Asia-Pacific | H10: Us | I10: United States | J10: North America | K10: Advanced_Logic_Chip | L10: =_xlfn.XLOOKUP(Trade_Flows[[#This Row],[hardware_type]],Helper_sheet!$D$2:$D$15,Helper_sheet!$E$2:$E$15,0,0) -> Chip | M10: Advanced | N10: 13686 | O10: 798.36 | P10: Intel Foundry Services | Q10: Trans-Pacific / Suez | R10: 0 | S10: 1 | T10: Low | U10: 8.29 | V10: 3.11 | W10: Un Comtrade/Wits/Sia Reports | X10: 0
A11: Tf000010 | B11: 2017 | C11: 2 | D11: 2017-Q2 | E11: Tw | F11: Taiwan | G11: Asia-Pacific | H11: Us | I11: United States | J11: North America | K11: Advanced_Logic_Chip | L11: =_xlfn.XLOOKUP(Trade_Flows[[#This Row],[hardware_type]],Helper_sheet!$D$2:$D$15,Helper_sheet!$E$2:$E$15,0,0) -> Chip | M11: Advanced | N11: 15862 | O11: 925.28 | P11: Tsmc | Q11: Trans-Pacific / Suez | R11: 0 | S11: 1 | T11: Low | U11: 8.23 | V11: 3.06 | W11: Un Comtrade/Wits/Sia Reports | X11: 0
A12: Tf000011 | B12: 2017 | C12: 3 | D12: 2017-Q3 | E12: Tw | F12: Taiwan | G12: Asia-Pacific | H12: Us | I12: United States | J12: North America | K12: Advanced_Logic_Chip | L12: =_xlfn.XLOOKUP(Trade_Flows[[#This Row],[hardware_type]],Helper_sheet!$D$2:$D$15,Helper_sheet!$E$2:$E$15,0,0) -> Chip | M12: Advanced | N12: 16995 | O12: 991.41 | P12: Intel Foundry Services | Q12: Trans-Pacific / Suez | R12: 0 | S12: 1 | T12: Low | U12: 8.1 | V12: 3.07 | W12: Un Comtrade/Wits/Sia Reports | X12: 0
A13: Tf000012 | B13: 2017 | C13: 4 | D13: 2017-Q4 | E13: Tw | F13: Taiwan | G13: Asia-Pacific | H13: Us | I13: United States | J13: North America | K13: Advanced_Logic_Chip | L13: =_xlfn.XLOOKUP(Trade_Flows[[#This Row],[hardware_type]],Helper_sheet!$D$2:$D$15,Helper_sheet!$E$2:$E$15,0,0) -> Chip | M13: Advanced | N13: 16164 | O13: 942.9 | P13: Intel Foundry Services | Q13: Trans-Pacific / Suez | R13: 0 | S13: 1 | T13: Low | U13: 8.34 | V13: 3.29 | W13: Un Comtrade/Wits/Sia Reports | X13: 0
... A5657: Tf005656 | B5657: 2025 | C5657: 4 | D5657: 2025-Q4 | E5657: Fr | F5657: France | G5657: Europe | H5657: Cn | I5657: China | J5657: Asia-Pacific | K5657: Semiconductor_Equipment | L5657: =_xlfn.XLOOKUP(Trade_Flows[[#This Row],[hardware_type]],Helper_sheet!$D$2:$D$15,Helper_sheet!$E$2:$E$15,0,0) -> Equipment | M5657: Standard | N5657: 830 | O5657: 415.05 | P5657: Lam Research | Q5657: Trans-Pacific / Suez | R5657: 0 | S5657: 1 | T5657: High | U5657: 2.77 | V5657: 8.67 | W5657: Un Comtrade/Wits/Sia Reports | X5657: 1

Sheet company_profile (2)
A1: company_id.1 | B1: company_name | C1: hq_country_code | D1: hq_country | E1: primary_domain | F1: year_founded | G1: strategic_focus | H1: year | I1: revenue_usd_bn | J1: rd_expenditure_usd_bn | K1: employees | L1: geopolitical_exposure | M1: sanction_risk_flag | N1: is_synthetic
A2: Co0001 | B2: NVIDIA | C2: US | D2: United States | E2: GPU/AI Accelerator | F2: 1993 | G2: GPU AI Training/Inference | H2: 2015 | I2: 4.7 | J2: 0.84 | K2: 9942 | L2: High | M2: 0 | N2: 0
A3: Co0002 | B3: NVIDIA | C3: US | D3: United States | E3: GPU/AI Accelerator | F3: 1993 | G3: GPU AI Training/Inference | H3: 2016 | I3: 6.1 | J3: 1.45 | K3: 11122 | L3: High | M3: 0 | N3: 0
A4: Co0003 | B4: NVIDIA | C4: US | D4: United States | E4: GPU/AI Accelerator | F4: 1993 | G4: GPU AI Training/Inference | H4: 2017 | I4: 9.37 | J4: 1.64 | K4: 13066 | L4: High | M4: 0 | N4: 0
A5: Co0004 | B5: NVIDIA | C5: US | D5: United States | E5: GPU/AI Accelerator | F5: 1993 | G5: GPU AI Training/Inference | H5: 2018 | I5: 11.61 | J5: 2.27 | K5: 13996 | L5: High | M5: 0 | N5: 0
A6: Co0005 | B6: NVIDIA | C6: US | D6: United States | E6: GPU/AI Accelerator | F6: 1993 | G6: GPU AI Training/Inference | H6: 2019 | I6: 10.57 | J6: 2.09 | K6: 14993 | L6: High | M6: 0 | N6: 0
A7: Co0006 | B7: NVIDIA | C7: US | D7: United States | E7: GPU/AI Accelerator | F7: 1993 | G7: GPU AI Training/Inference | H7: 2020 | I7: 11.19 | J7: 2.56 | K7: 19352 | L7: High | M7: 0 | N7: 0
A8: Co0007 | B8: NVIDIA | C8: US | D8: United States | E8: GPU/AI Accelerator | F8: 1993 | G8: GPU AI Training/Inference | H8: 2021 | I8: 17.33 | J8: 4.15 | K8: 22695 | L8: High | M8: 0 | N8: 0
A9: Co0008 | B9: NVIDIA | C9: US | D9: United States | E9: GPU/AI Accelerator | F9: 1993 | G9: GPU AI Training/Inference | H9: 2022 | I9: 25.76 | J9: 4.89 | K9: 30109 | L9: High | M9: 0 | N9: 0
A10: Co0009 | B10: NVIDIA | C10: US | D10: United States | E10: GPU/AI Accelerator | F10: 1993 | G10: GPU AI Training/Inference | H10: 2023 | I10: 63.47 | J10: 14.06 | K10: 35389 | L10: High | M10: 0 | N10: 0
A11: Co0010 | B11: NVIDIA | C11: US | D11: United States | E11: GPU/AI Accelerator | F11: 1993 | G11: GPU AI Training/Inference | H11: 2024 | I11: 133.06 | J11: 30.19 | K11: 40795 | L11: High | M11: 0 | N11: 1
A12: Co0011 | B12: NVIDIA | C12: US | D12: United States | E12: GPU/AI Accelerator | F12: 1993 | G12: GPU AI Training/Inference | H12: 2025 | I12: 177.89 | J12: 33.2 | K12: 45103 | L12: High | M12: 0 | N12: 1
A13: Co0012 | B13: AMD | C13: US | D13: United States | E13: GPU/CPU | F13: 1969 | G13: GPU CPU Data Center | H13: 2015 | I13: 3.78 | J13: 0.65 | K13: 9602 | L13: High | M13: 0 | N13: 0
... A243: Co0242 | B243: STC | C243: SA | D243: Saudi Arabia | E243: Telecom/AI | F243: 1998 | G243: AI Infrastructure Cloud | H243: 2025 | I243: 9.99 | J243: 0.95 | K243: 16773 | L243: Medium | M243: 0 | N243: 1

Sheet Buisness Questions
B1: What is the total global semiconductor trade value represented in the dataset?
B2: How many companies are included in the semiconductor ecosystem?
B3: How many countries participate in global semiconductor exports and imports?
B4: What percentage of semiconductor trade is subject to export controls?
B5: What percentage of total semiconductor trade falls under high geopolitical sensitivity?
B6: How has global semiconductor trade value changed over time (2015–2025)?
B7: Which hardware segments generate the highest semiconductor trade value?
B8: Which semiconductor equipment types generate the highest trade value?
B9: Which international trade routes generate the highest semiconductor trade value?
B10: Which countries dominate global semiconductor exports?
B11: Which primary suppliers dominate the global semiconductor supply chain?
B12: Which semiconductor companies generate the highest revenue?
... B22: Which primary suppliers dominate the global semiconductor supply chain?

Sheet Pivot_Sheet
A3: Total_trade_usd | B3: Total | E3: Total_Trading_Countries | F3: Total | H3: Countries_Dominating_in_Exports | K3: Most_Value_Generating_Trade_route | N3: Sum of trade_value_usd_millions | S3: Sum of rd_expenditure_usd_bn
A4: Total | B4: 3906768.9 | E4: Total | F4: 11 | H4: exporter_country | I4: Total | K4: trade_route | L4: Total | N4: hardware_category | O4: Total | S4: company_name | T4: Total
E5: Total Exporting | H5: Netherlands | I5: 0.42179132 | K5: Trans-Pacific / Suez | L5: 2441183.5 | N5: Advanced | O5: 1678342.1 | S5: Samsung | T5: 0.30002057
A6: Total_Companies | B6: Total | H6: Taiwan | I6: 0.15777158 | K6: Asia-Pacific Maritime | L6: 1051780.2 | N6: Standard | O6: 2228426.8 | S6: Intel | T6: 0.18864092
A7: Total | B7: 22 | E7: Total_Importing_countries | F7: Total | H7: United States | I7: 0.13519169 | K7: Intra-Atlantic | L7: 210703.2 | N7: Grand Total | O7: 3906768.9 | S7: TSMC | T7: 0.14790199
E8: Total | F8: 11 | H8: Japan | I8: 0.11627504 | K8: Middle-East/South-Asia Corridor | L8: 203101.91 | S8: NVIDIA | T8: 0.12513498
A9: Companies_Revenue_usd_bn | E9: Total Importing | H9: South Korea | I9: 0.098917165 | K9: Grand Total | L9: 3906768.9 | S9: ASML | T9: 0.048040829
A10: company_name | B10: Total | H10: China | I10: 0.036804341 | K10: Most value generating trade route | N10: Share_% | S10: SK Hynix | T10: 0.044916954
A11: Samsung | B11: 269.9 | H11: Germany | I11: 0.021893091 | K11: Hardware_Traded | N11: primary_supplier | O11: Total | S11: Qualcomm | T11: 0.041073173
A12: NVIDIA | B12: 177.89 | H12: United Arab Emirates | I12: 0.0045296032 | K12: hardware_type | L12: Total | N12: Asml | O12: 0.4131529 | S12: AMD | T12: 0.038077853
A13: TSMC | B13: 107.59 | H13: France | I13: 0.0042544607 | K13: Duv_Lithography_Machine | L13: 1255720.9 | N13: Canon | O13: 0.14652089 | S13: Micron Technology | T13: 0.036702319
A14: Intel | B14: 80.06 | H14: India | I14: 0.0025717101 | K14: Euv_Lithography_Machine | L14: 684073.02 | N14: Nikon | O14: 0.14419907 | S14: Shin-Etsu Chemical | T14: 0.02949041
A15: SK Hynix | B15: 68.28 | H15: Grand Total | I15: 1 | K15: Ai_Accelerator | L15: 337781.76 | N15: Micron | O15: 0.050716478 | S15: Grand Total | T15: 1
A16: Qualcomm | B16: 46.87 | K16: Semiconductor_Equipment | L16: 310185.36 | N16: Sk Hynix | O16: 0.049670812
A17: Micron Technology | B17: 43.34 | H17: Country_dominating supply | K17: Gpu_High_End | L17: 284097.94 | N17: Samsung | O17: 0.049478869
A18: ASML | B18: 37.64 | H18: Sum of trade_value_usd_millions | K18: Advanced_Logic_Chip | L18: 267261.28 | N18: Nvidia | O18: 0.043017447
A19: Applied Materials | B19: 31.98 | H19: importer_country | I19: Total | K19: Dram | L19: 214824.05 | N19: Amd | O19: 0.040013022
A20: AMD | B20: 28.5 | H20: China | I20: 0.20482694 | K20: Nand_Flash | L20: 164236 | N20: Tsmc | O20: 0.03212547
A21: Grand Total | B21: 269.9 | H21: Taiwan | I21: 0.20387549 | K21: Consumer_Chip | L21: 135859.21 | N21: Intel Foundry Services | O21: 0.03110504
H22: South Korea | I22: 0.17049215 | K22: Hbm_Memory | L22: 105128.11 | N22: Grand Total | O22: 1
H23: United States | I23: 0.16170413 | K23: Grand Total | L23: 3759167.6
H24: India | I24: 0.087872152 | N24: Companies Dominating
H25: Japan | I25: 0.077389129 | K25: Hardware type traded
H26: Germany | I26: 0.034272713
H27: United Arab Emirates | I27: 0.023732205 | W27: Count of trade_route
H28: Saudi Arabia | I28: 0.015627515 | S28: Q14 | W28: geopolitical_sensitivity | X28: Total
E29: Time-Trend | H29: France | I29: 0.012264345 | W29: High | X29: 1872
H30: Pakistan | I30: 0.0079432444 | O30: geopolitical_sensitivity | P30: High | W30: Low | X30: 3036
H31: Grand Total | I31: 1 | W31: Medium | X31: 748
O32: Count of geopolitical_sensitivity | W32: Grand Total | X32: 5656
H33: Most Importing Countries | L33: geopolitical_sensitivity | M33: High | O33: exporter_region | P33: Total
O34: Asia-Pacific | P34: 1320 | S34: Sum of Growth
L35: High_Geopolitical_Sensitivity_Routes | O35: Europe | P35: 314 | S35: Company_name | T35: Total
L36: trade_route | M36: Total | O36: North America | P36: 238 | S36: Cambricon | T36: 145
L37: Asia-Pacific Maritime | M37: 880 | O37: Grand Total | P37: 1872 | S37: G42 | T37: 121.9
L38: Middle-East/South-Asia Corridor | M38: 352 | S38: NVIDIA | T38: 36.848936
L39: Trans-Pacific / Suez | M39: 640 | S39: AMD | T39: 6.5396825
B40: Sum of Trade_Value_per_Unit | H40: Sum of trade_value_usd_millions | I40: export_control_applied | L40: Grand Total | M40: 1872 | O40: Q12 | S40: ASML | T40: 5.0320513
B41: Hardware_Segment | C41: hardware_type | D41: Total | H41: Hardware_Segment | I41: 0 | J41: 1 | K41: Grand Total | L41: Q10 | S41: KLA Corporation | T41: 4.1438596
B42: Chip | C42: Advanced_Logic_Chip | D42: 58534.285 | H42: Chip | I42: 0.3950714 | J42: 0.0040458882 | K42: 0.39911729 | L42: geopolitical_sensitivity | M42: High | S42: Tokyo Electron | T42: 3.8407534
...

Sheet Dashboard
A1: GLOBAL SEMICONDUCTOR TRADE INTELLIGENCE DASHBOARD TRADE ANALYSIS | SUPPLY CHAIN | GEOPOLITICAL RISK (2015–2025)

Sheet SupportingAnalysis

Sheet Helper_sheet
A1: Hardware_type | B1: Avearge price per unit | D1: Hardware_type | E1: Segment | H1: Company_name | I1: Revenue_2015 | J1: Revenue_2025 | K1: Growth
A2: Advanced_Logic_Chip | B2: =SUMIFS(Trade_Flows!O:O,Trade_Flows!K:K,Helper_sheet!A2) / SUMIFS(Trade_Flows!N:N,Trade_Flows!K:K,Helper_sheet!A2) * 1000000 -> 58534.285 | D2: Advanced_Logic_Chip | E2: Chip | H2: NVIDIA | I2: {=_xlfn.XLOOKUP($H2&2015,company_profile[company_name]&company_profile[year],company_profile[revenue_usd_bn],0,0)} -> 4.7 | J2: {=_xlfn.XLOOKUP($H2&2025,company_profile[company_name]&company_profile[year],company_profile[revenue_usd_bn],0,0)} -> 177.89 | K2: =IF($I2=0,"N/A",($J2-$I2)/$I2) -> 36.848936
A3: Gpu_High_End | B3: =SUMIFS(Trade_Flows!O:O,Trade_Flows!K:K,Helper_sheet!A3) / SUMIFS(Trade_Flows!N:N,Trade_Flows!K:K,Helper_sheet!A3) * 1000000 -> 60230.374 | D3: Gpu_High_End | E3: Chip | H3: AMD | I3: {=_xlfn.XLOOKUP($H3&2015,company_profile[company_name]&company_profile[year],company_profile[revenue_usd_bn],0,0)} -> 3.78 | J3: {=_xlfn.XLOOKUP($H3&2025,company_profile[company_name]&company_profile[year],company_profile[revenue_usd_bn],0,0)} -> 28.5 | K3: =IF($I3=0,"N/A",($J3-$I3)/$I3) -> 6.5396825
A4: Ai_Accelerator | B4: =SUMIFS(Trade_Flows!O:O,Trade_Flows!K:K,Helper_sheet!A4) / SUMIFS(Trade_Flows!N:N,Trade_Flows!K:K,Helper_sheet!A4) * 1000000 -> 61927.638 | D4: Ai_Accelerator | E4: Chip | H4: Intel | I4: {=_xlfn.XLOOKUP($H4&2015,company_profile[company_name]&company_profile[year],company_profile[revenue_usd_bn],0,0)} -> 52.79 | J4: {=_xlfn.XLOOKUP($H4&2025,company_profile[company_name]&company_profile[year],company_profile[revenue_usd_bn],0,0)} -> 57.42 | K4: =IF($I4=0,"N/A",($J4-$I4)/$I4) -> 0.087706005
A5: Dram | B5: =SUMIFS(Trade_Flows!O:O,Trade_Flows!K:K,Helper_sheet!A5) / SUMIFS(Trade_Flows!N:N,Trade_Flows!K:K,Helper_sheet!A5) * 1000000 -> 51287.695 | D5: Dram | E5: Chip | H5: Qualcomm | I5: {=_xlfn.XLOOKUP($H5&2015,company_profile[company_name]&company_profile[year],company_profile[revenue_usd_bn],0,0)} -> 25.89 | J5: {=_xlfn.XLOOKUP($H5&2025,company_profile[company_name]&company_profile[year],company_profile[revenue_usd_bn],0,0)} -> 46.87 | K5: =IF($I5=0,"N/A",($J5-$I5)/$I5) -> 0.81035149
A6: Nand_Flash | B6: =SUMIFS(Trade_Flows!O:O,Trade_Flows!K:K,Helper_sheet!A6) / SUMIFS(Trade_Flows!N:N,Trade_Flows!K:K,Helper_sheet!A6) * 1000000 -> 50002.162 | D6: Nand_Flash | E6: Chip | H6: Applied Materials | I6: {=_xlfn.XLOOKUP($H6&2015,company_profile[company_name]&company_profile[year],company_profile[revenue_usd_bn],0,0)} -> 9.5 | J6: {=_xlfn.XLOOKUP($H6&2025,company_profile[company_name]&company_profile[year],company_profile[revenue_usd_bn],0,0)} -> 31.98 | K6: =IF($I6=0,"N/A",($J6-$I6)/$I6) -> 2.3663158
A7: Consumer_Chip | B7: =SUMIFS(Trade_Flows!O:O,Trade_Flows!K:K,Helper_sheet!A7) / SUMIFS(Trade_Flows!N:N,Trade_Flows!K:K,Helper_sheet!A7) * 1000000 -> 50629.938 | D7: Consumer_Chip | E7: Chip | H7: Lam Research | I7: {=_xlfn.XLOOKUP($H7&2015,company_profile[company_name]&company_profile[year],company_profile[revenue_usd_bn],0,0)} -> 5.55 | J7: {=_xlfn.XLOOKUP($H7&2025,company_profile[company_name]&company_profile[year],company_profile[revenue_usd_bn],0,0)} -> 21.86 | K7: =IF($I7=0,"N/A",($J7-$I7)/$I7) -> 2.9387387
A8: Semiconductor_Equipment | B8: =SUMIFS(Trade_Flows!O:O,Trade_Flows!K:K,Helper_sheet!A8) / SUMIFS(Trade_Flows!N:N,Trade_Flows!K:K,Helper_sheet!A8) * 1000000 -> 102632.49 | D8: Semiconductor_Equipment | E8: Equipment | H8: KLA Corporation | I8: {=_xlfn.XLOOKUP($H8&2015,company_profile[company_name]&company_profile[year],company_profile[revenue_usd_bn],0,0)} -> 2.85 | J8: {=_xlfn.XLOOKUP($H8&2025,company_profile[company_name]&company_profile[year],company_profile[revenue_usd_bn],0,0)} -> 14.66 | K8: =IF($I8=0,"N/A",($J8-$I8)/$I8) -> 4.1438596
A9: Eda_Software | B9: =SUMIFS(Trade_Flows!O:O,Trade_Flows!K:K,Helper_sheet!A9) / SUMIFS(Trade_Flows!N:N,Trade_Flows!K:K,Helper_sheet!A9) * 1000000 -> 60003.951 | D9: Eda_Software | E9: Software | H9: Micron Technology | I9: {=_xlfn.XLOOKUP($H9&2015,company_profile[company_name]&company_profile[year],company_profile[revenue_usd_bn],0,0)} -> 13.3 | J9: {=_xlfn.XLOOKUP($H9&2025,company_profile[company_name]&company_profile[year],company_profile[revenue_usd_bn],0,0)} -> 43.34 | K9: =IF($I9=0,"N/A",($J9-$I9)/$I9) -> 2.2586466
A10: Hbm_Memory | B10: =SUMIFS(Trade_Flows!O:O,Trade_Flows!K:K,Helper_sheet!A10) / SUMIFS(Trade_Flows!N:N,Trade_Flows!K:K,Helper_sheet!A10) * 1000000 -> 53542.409 | D10: Hbm_Memory | E10: Chip | H10: ASML | I10: {=_xlfn.XLOOKUP($H10&2015,company_profile[company_name]&company_profile[year],company_profile[revenue_usd_bn],0,0)} -> 6.24 | J10: {=_xlfn.XLOOKUP($H10&2025,company_profile[company_name]&company_profile[year],company_profile[revenue_usd_bn],0,0)} -> 37.64 | K10: =IF($I10=0,"N/A",($J10-$I10)/$I10) -> 5.0320513
A11: Euv_Lithography_Machine | B11: =SUMIFS(Trade_Flows!O:O,Trade_Flows!K:K,Helper_sheet!A11) / SUMIFS(Trade_Flows!N:N,Trade_Flows!K:K,Helper_sheet!A11) * 1000000 -> 1.7441943e+08 | D11: Euv_Lithography_Machine | E11: Equipment | H11: TSMC | I11: {=_xlfn.XLOOKUP($H11&2015,company_profile[company_name]&company_profile[year],company_profile[revenue_usd_bn],0,0)} -> 25.43 | J11: {=_xlfn.XLOOKUP($H11&2025,company_profile[company_name]&company_profile[year],company_profile[revenue_usd_bn],0,0)} -> 107.59 | K11: =IF($I11=0,"N/A",($J11-$I11)/$I11) -> 3.2308297
A12: Duv_Lithography_Machine | B12: =SUMIFS(Trade_Flows!O:O,Trade_Flows!K:K,Helper_sheet!A12) / SUMIFS(Trade_Flows!N:N,Trade_Flows!K:K,Helper_sheet!A12) * 1000000 -> 54093259 | D12: Duv_Lithography_Machine | E12: Equipment | H12: MediaTek | I12: {=_xlfn.XLOOKUP($H12&2015,company_profile[company_name]&company_profile[year],company_profile[revenue_usd_bn],0,0)} -> 5.95 | J12: {=_xlfn.XLOOKUP($H12&2025,company_profile[company_name]&company_profile[year],company_profile[revenue_usd_bn],0,0)} -> 20.5 | K12: =IF($I12=0,"N/A",($J12-$I12)/$I12) -> 2.4453782
A13: Chemical_Materials | B13: =SUMIFS(Trade_Flows!O:O,Trade_Flows!K:K,Helper_sheet!A13) / SUMIFS(Trade_Flows!N:N,Trade_Flows!K:K,Helper_sheet!A13) * 1000000 -> 501628.11 | D13: Chemical_Materials | E13: Material | H13: Samsung | I13: {=_xlfn.XLOOKUP($H13&2015,company_profile[company_name]&company_profile[year],company_profile[revenue_usd_bn],0,0)} -> 169.74 | J13: {=_xlfn.XLOOKUP($H13&2025,company_profile[company_name]&company_profile[year],company_profile[revenue_usd_bn],0,0)} -> 269.9 | K13: =IF($I13=0,"N/A",($J13-$I13)/$I13) -> 0.59007894
... A15: Surveillance_Chip | B15: =SUMIFS(Trade_Flows!O:O,Trade_Flows!K:K,Helper_sheet!A15) / SUMIFS(Trade_Flows!N:N,Trade_Flows!K:K,Helper_sheet!A15) * 1000000 -> 50007.595 | D15: Surveillance_Chip | E15: Chip | H15: Tokyo Electron | I15: {=_xlfn.XLOOKUP($H15&2015,company_profile[company_name]&company_profile[year],company_profile[revenue_usd_bn],0,0)} -> 5.84 | J15: {=_xlfn.XLOOKUP($H15&2025,company_profile[company_name]&company_profile[year],company_profile[revenue_usd_bn],0,0)} -> 28.27 | K15: =IF($I15=0,"N/A",($J15-$I15)/$I15) -> 3.8407534
H16: Shin-Etsu Chemical | I16: {=_xlfn.XLOOKUP($H16&2015,company_profile[company_name]&company_profile[year],company_profile[revenue_usd_bn],0,0)} -> 12.1 | J16: {=_xlfn.XLOOKUP($H16&2025,company_profile[company_name]&company_profile[year],company_profile[revenue_usd_bn],0,0)} -> 25.99 | K16: =IF($I16=0,"N/A",($J16-$I16)/$I16) -> 1.1479339
H17: Huawei HiSilicon | I17: {=_xlfn.XLOOKUP($H17&2015,company_profile[company_name]&company_profile[year],company_profile[revenue_usd_bn],0,0)} -> 8.22 | J17: {=_xlfn.XLOOKUP($H17&2025,company_profile[company_name]&company_profile[year],company_profile[revenue_usd_bn],0,0)} -> 12.17 | K17: =IF($I17=0,"N/A",($J17-$I17)/$I17) -> 0.48053528
H18: SMIC | I18: {=_xlfn.XLOOKUP($H18&2015,company_profile[company_name]&company_profile[year],company_profile[revenue_usd_bn],0,0)} -> 2.15 | J18: {=_xlfn.XLOOKUP($H18&2025,company_profile[company_name]&company_profile[year],company_profile[revenue_usd_bn],0,0)} -> 7.9 | K18: =IF($I18=0,"N/A",($J18-$I18)/$I18) -> 2.6744186
H19: Cambricon | I19: {=_xlfn.XLOOKUP($H19&2015,company_profile[company_name]&company_profile[year],company_profile[revenue_usd_bn],0,0)} -> 0.01 | J19: {=_xlfn.XLOOKUP($H19&2025,company_profile[company_name]&company_profile[year],company_profile[revenue_usd_bn],0,0)} -> 1.46 | K19: =IF($I19=0,"N/A",($J19-$I19)/$I19) -> 145
H20: Biren Technology | I20: {=_xlfn.XLOOKUP($H20&2015,company_profile[company_name]&company_profile[year],company_profile[revenue_usd_bn],0,0)} -> 0 | J20: {=_xlfn.XLOOKUP($H20&2025,company_profile[company_name]&company_profile[year],company_profile[revenue_usd_bn],0,0)} -> 0.2 | K20: =IF($I20=0,"N/A",($J20-$I20)/$I20) -> N/A
H21: G42 | I21: {=_xlfn.XLOOKUP($H21&2015,company_profile[company_name]&company_profile[year],company_profile[revenue_usd_bn],0,0)} -> 0.1 | J21: {=_xlfn.XLOOKUP($H21&2025,company_profile[company_name]&company_profile[year],company_profile[revenue_usd_bn],0,0)} -> 12.29 | K21: =IF($I21=0,"N/A",($J21-$I21)/$I21) -> 121.9
H22: Reliance Jio | I22: {=_xlfn.XLOOKUP($H22&2015,company_profile[company_name]&company_profile[year],company_profile[revenue_usd_bn],0,0)} -> 0 | J22: {=_xlfn.XLOOKUP($H22&2025,company_profile[company_name]&company_profile[year],company_profile[revenue_usd_bn],0,0)} -> 25.17 | K22: =IF($I22=0,"N/A",($J22-$I22)/$I22) -> N/A
H23: STC | I23: {=_xlfn.XLOOKUP($H23&2015,company_profile[company_name]&company_profile[year],company_profile[revenue_usd_bn],0,0)} -> 5.24 | J23: {=_xlfn.XLOOKUP($H23&2025,company_profile[company_name]&company_profile[year],company_profile[revenue_usd_bn],0,0)} -> 9.99 | K23: =IF($I23=0,"N/A",($J23-$I23)/$I23) -> 0.90648855
A36: TOTAL TRADE VALUE (USD) | B36: =Pivot_Sheet!B4 -> 3906768.9
A37: TOTAL TRADING COUNTRIES | B37: =COUNTA(A44:A55) -> 12
A38: TOTAL EXPORTING COMPANIES | B38: =Pivot_Sheet!B7 -> 22
A39: EXPORT-CONTROLLED TRADE | B39: =Pivot_Sheet!F69 -> 0.017857852
A40: HIGH RISK TRADE SHARE | B40: =Pivot_Sheet!J66 -> 0.44544828
A43: TOTAL COUNTRIES
A44: Taiwan
A45: United States
A46: Netherlands
A47: South Korea
A48: Japan
A49: Germany
A50: China
A51: India
A52: United Arab Emirates
A53: Saudi Arabia
A54: France
A55: Pakistan
